<?xml version="1.0"?>
<!-- =================================================================================== -->
<!-- |    This document was autogenerated by xacro from
/home/robot/franka_ros_ws/src/franka_ros/franka_description/robots/panda/panda.urdf.xacro | -->
<!-- |    EDITING THIS FILE BY HAND IS NOT RECOMMENDED                                 | -->
<!-- =================================================================================== -->
<robot name="panda">
    <!-- sub-link defining detailed meshes for collision with environment -->
    <link name="panda_link0">
        <inertial>
            <origin xyz="-0.041018 -0.00014 0.049974" rpy="0 0 0" />
            <mass value="0.629769" />
            <inertia ixx="0.00315" ixy="8.2904e-07" ixz="0.00015" iyy="0.00388" iyz="8.2299e-06"
                izz="0.004285" />
        </inertial>
        <visual>
            <origin xyz="0 0 0" rpy="0 0 0" />
            <geometry>
                <mesh filename="package://franka_description/meshes/visual/link0.dae" />
            </geometry>
        </visual>
        <collision>
            <origin xyz="0 0 0" rpy="0 0 0" />
            <geometry>
                <mesh filename="package://franka_description/meshes/collision/link0.stl" />
            </geometry>
            <surface>
                <friction>
                    <ode mu="1" mu2="1" fdir1="0 0 0" slip1="0" slip2="0" />
                    <torsional coefficient="1" patch_radius="0" surface_radius="0"
                        use_patch_radius="1">
                        <ode slip="0" />
                    </torsional>
                </friction>
                <bounce restitution_coefficient="0" threshold="1e+06" />
                <contact>
                    <ode soft_cfm="0" soft_erp="0.2" kp="1e+13" kd="1" max_vel="0.01" min_depth="0" />
                    <bullet split_impulse="1" split_impulse_penetration_threshold="-0.01"
                        soft_cfm="0" soft_erp="0.2" kp="1e+13" kd="1" />
                </contact>
            </surface>
        </collision>
    </link>
    <!-- sub-link defining coarse geometries of real robot's internal self-collision -->
    <link name="panda_link0_sc">
        <collision>
            <origin rpy="0 1.5707963267948966 0" xyz="-0.075 0 0.06" />
            <geometry>
                <cylinder length="0.03" radius="0.09" />
            </geometry>
        </collision>
        <collision>
            <origin xyz="-0.06 0 0.06" />
            <geometry>
                <sphere radius="0.09" />
            </geometry>
        </collision>
        <collision>
            <origin xyz="-0.09 0 0.06" />
            <geometry>
                <sphere radius="0.09" />
            </geometry>
        </collision>
    </link>
    <!-- fixed joint between both sub-links -->
    <joint name="panda_link0_sc_joint" type="fixed">
        <origin rpy="0 0 0" />
        <parent link="panda_link0" />
        <child link="panda_link0_sc" />
    </joint>
    <!-- sub-link defining detailed meshes for collision with environment -->
    <link name="panda_link1">
        <inertial>
            <origin xyz="0.003875 0.002081 -0.04762" rpy="0 0 0" />
            <mass value="4.97068" />
            <inertia ixx="0.70337" ixy="-0.000139" ixz="0.006772" iyy="0.70661" iyz="0.019169"
                izz="0.009117" />
        </inertial>
        <visual>
            <origin xyz="0 0 0" rpy="0 0 0" />
            <geometry>
                <mesh filename="package://franka_description/meshes/visual/link1.dae" />
            </geometry>
        </visual>
        <collision>
            <origin xyz="0 0 0" rpy="0 0 0" />
            <geometry>
                <mesh filename="package://franka_description/meshes/collision/link1.stl" />
            </geometry>
            <surface>
                <friction>
                    <ode mu="1" mu2="1" fdir1="0 0 0" slip1="0"
                        slip2="0" />
                    <torsional coefficient="1" patch_radius="0" surface_radius="0"
                        use_patch_radius="1">
                        <ode slip="0" />
                    </torsional>
                </friction>
                <bounce restitution_coefficient="0" threshold="1e+06" />
                <contact>
                    <ode soft_cfm="0" soft_erp="0.2" kp="1e+13" kd="1" max_vel="0.01" min_depth="0" />
                    <bullet split_impulse="1" split_impulse_penetration_threshold="-0.01"
                        soft_cfm="0" soft_erp="0.2" kp="1e+13" kd="1" />
                </contact>
            </surface>
        </collision>
    </link>
    <!-- sub-link defining coarse geometries of real robot's internal self-collision -->
    <link name="panda_link1_sc">
        <collision>
            <origin rpy="0 0 0" xyz="0 0 -0.1915" />
            <geometry>
                <cylinder length="0.283" radius="0.09" />
            </geometry>
        </collision>
        <collision>
            <origin xyz="0 0 -0.05000000000000002" />
            <geometry>
                <sphere radius="0.09" />
            </geometry>
        </collision>
        <collision>
            <origin xyz="0 0 -0.33299999999999996" />
            <geometry>
                <sphere radius="0.09" />
            </geometry>
        </collision>
    </link>
    <!-- fixed joint between both sub-links -->
    <joint name="panda_link1_sc_joint" type="fixed">
        <origin rpy="0 0 0" />
        <parent link="panda_link1" />
        <child link="panda_link1_sc" />
    </joint>
    <joint name="panda_joint1" type="revolute">
        <origin rpy="0 0 0" xyz="0 0 0.333" />
        <parent link="panda_link0" />
        <child link="panda_link1" />
        <axis xyz="0 0 1" />
        <limit effort="87.0" lower="-2.8973" upper="2.8973" velocity="2.175" />
        <safety_controller k_position="100.0" k_velocity="40.0" soft_lower_limit="-2.8973"
            soft_upper_limit="2.8973" />
        <dynamics D="1" K="7000" damping="0.003" friction="0.0" mu_coulomb="0" mu_viscous="16" />
    </joint>
    <!-- sub-link defining detailed meshes for collision with environment -->
    <link name="panda_link2">
        <inertial>
            <origin xyz="-0.003141 -0.02872 0.003495" rpy="0 0 0" />
            <mass value="0.646926" />
            <inertia ixx="0.007962" ixy="-0.003925" ixz="0.010254" iyy="0.02811" iyz="0.000704"
                izz="0.025995" />
        </inertial>
        <visual>
            <origin xyz="0 0 0" rpy="0 0 0" />
            <geometry>
                <mesh filename="package://franka_description/meshes/visual/link2.dae" />
            </geometry>
        </visual>
        <collision>
            <origin xyz="0 0 0" rpy="0 0 0" />
            <geometry>
                <mesh filename="package://franka_description/meshes/collision/link2.stl" />
            </geometry>
            <surface>
                <friction>
                    <ode mu="1" mu2="1" fdir1="0 0 0" slip1="0" slip2="0" />
                    <torsional coefficient="1" patch_radius="0" surface_radius="0"
                        use_patch_radius="1">
                        <ode slip="0" />
                    </torsional>
                </friction>
                <bounce restitution_coefficient="0" threshold="1e+06" />
                <contact>
                    <ode soft_cfm="0" soft_erp="0.2" kp="1e+13" kd="1" max_vel="0.01" min_depth="0" />
                    <bullet split_impulse="1" split_impulse_penetration_threshold="-0.01"
                        soft_cfm="0" soft_erp="0.2" kp="1e+13" kd="1" />
                </contact>
            </surface>
        </collision>
    </link>
    <!-- sub-link defining coarse geometries of real robot's internal self-collision -->
    <link name="panda_link2_sc">
        <collision>
            <origin rpy="0 0 0" xyz="0 0 0" />
            <geometry>
                <cylinder length="0.12" radius="0.09" />
            </geometry>
        </collision>
        <collision>
            <origin xyz="0 0 0.06" />
            <geometry>
                <sphere radius="0.09" />
            </geometry>
        </collision>
        <collision>
            <origin xyz="0 0 -0.06" />
            <geometry>
                <sphere radius="0.09" />
            </geometry>
        </collision>
    </link>
    <!-- fixed joint between both sub-links -->
    <joint name="panda_link2_sc_joint" type="fixed">
        <origin rpy="0 0 0" />
        <parent link="panda_link2" />
        <child link="panda_link2_sc" />
    </joint>
    <joint name="panda_joint2" type="revolute">
        <origin rpy="-1.5707963267948966 0 0" xyz="0 0 0" />
        <parent link="panda_link1" />
        <child link="panda_link2" />
        <axis xyz="0 0 1" />
        <limit effort="87.0" lower="-1.7628" upper="1.7628" velocity="2.175" />
        <safety_controller k_position="100.0" k_velocity="40.0" soft_lower_limit="-1.7628"
            soft_upper_limit="1.7628" />
        <dynamics D="1" K="7000" damping="0.003" friction="0.0" mu_coulomb="0" mu_viscous="16" />
    </joint>
    <!-- sub-link defining detailed meshes for collision with environment -->
    <link name="panda_link3">
        <inertial>
            <origin xyz="0.027518 0.039252 -0.066502" rpy="0 0 0" />
            <mass value="3.2286" />
            <inertia ixx="0.037242" ixy="-0.004761" ixz="-0.011396" iyy="0.036155" iyz="-0.012805"
                izz="0.01083" />
        </inertial>
        <visual>
            <origin xyz="0 0 0" rpy="0 0 0" />
            <geometry>
                <mesh filename="package://franka_description/meshes/visual/link3.dae" />
            </geometry>
        </visual>
        <collision>
            <origin xyz="0 0 0" rpy="0 0 0" />
            <geometry>
                <mesh filename="package://franka_description/meshes/collision/link3.stl" />
            </geometry>
            <surface>
                <friction>
                    <ode mu="1" mu2="1" fdir1="0 0 0" slip1="0" slip2="0" />
                    <torsional coefficient="1" patch_radius="0" surface_radius="0"
                        use_patch_radius="1">
                        <ode slip="0" />
                    </torsional>
                </friction>
                <bounce restitution_coefficient="0" threshold="1e+06" />
                <contact>
                    <ode soft_cfm="0" soft_erp="0.2" kp="1e+13" kd="1" max_vel="0.01" min_depth="0" />
                    <bullet split_impulse="1" split_impulse_penetration_threshold="-0.01"
                        soft_cfm="0" soft_erp="0.2" kp="1e+13" kd="1" />
                </contact>
            </surface>
        </collision>
    </link>
    <!-- sub-link defining coarse geometries of real robot's internal self-collision -->
    <link name="panda_link3_sc">
        <collision>
            <origin rpy="0 0 0" xyz="0 0 -0.145" />
            <geometry>
                <cylinder length="0.15" radius="0.09" />
            </geometry>
        </collision>
        <collision>
            <origin xyz="0 0 -0.06999999999999999" />
            <geometry>
                <sphere radius="0.09" />
            </geometry>
        </collision>
        <collision>
            <origin xyz="0 0 -0.21999999999999997" />
            <geometry>
                <sphere radius="0.09" />
            </geometry>
        </collision>
    </link>
    <!-- fixed joint between both sub-links -->
    <joint name="panda_link3_sc_joint" type="fixed">
        <origin rpy="0 0 0" />
        <parent link="panda_link3" />
        <child link="panda_link3_sc" />
    </joint>
    <joint name="panda_joint3" type="revolute">
        <origin rpy="1.5707963267948966 0 0" xyz="0 -0.316 0" />
        <parent link="panda_link2" />
        <child link="panda_link3" />
        <axis xyz="0 0 1" />
        <limit effort="87.0" lower="-2.8973" upper="2.8973" velocity="2.175" />
        <safety_controller k_position="100.0" k_velocity="40.0" soft_lower_limit="-2.8973"
            soft_upper_limit="2.8973" />
        <dynamics D="1" K="7000" damping="0.003" friction="0.0" mu_coulomb="0" mu_viscous="16" />
    </joint>
    <!-- sub-link defining detailed meshes for collision with environment -->
    <link name="panda_link4">
        <inertial>
            <origin xyz="-0.05317 0.104419 0.027454" rpy="0 0 0" />
            <mass value="3.5879" />
            <inertia ixx="0.025853" ixy="0.007796" ixz="-0.001332" iyy="0.019552" iyz="0.008641"
                izz="0.028323" />
        </inertial>
        <visual>
            <origin xyz="0 0 0" rpy="0 0 0" />
            <geometry>
                <mesh filename="package://franka_description/meshes/visual/link4.dae" />
            </geometry>
        </visual>
        <collision>
            <origin xyz="0 0 0" rpy="0 0 0" />
            <geometry>
                <mesh filename="package://franka_description/meshes/collision/link4.stl" />
            </geometry>
            <surface>
                <friction>
                    <ode mu="1" mu2="1" fdir1="0 0 0" slip1="0" slip2="0" />
                    <torsional coefficient="1" patch_radius="0" surface_radius="0"
                        use_patch_radius="1">
                        <ode slip="0" />
                    </torsional>
                </friction>
                <bounce restitution_coefficient="0" threshold="1e+06" />
                <contact>
                    <ode soft_cfm="0" soft_erp="0.2" kp="1e+13" kd="1" max_vel="0.01" min_depth="0" />
                    <bullet split_impulse="1" split_impulse_penetration_threshold="-0.01"
                        soft_cfm="0" soft_erp="0.2" kp="1e+13" kd="1" />
                </contact>
            </surface>
        </collision>
    </link>
    <!-- sub-link defining coarse geometries of real robot's internal self-collision -->
    <link name="panda_link4_sc">
        <collision>
            <origin rpy="0 0 0" xyz="0 0 0" />
            <geometry>
                <cylinder length="0.12" radius="0.09" />
            </geometry>
        </collision>
        <collision>
            <origin xyz="0 0 0.06" />
            <geometry>
                <sphere radius="0.09" />
            </geometry>
        </collision>
        <collision>
            <origin xyz="0 0 -0.06" />
            <geometry>
                <sphere radius="0.09" />
            </geometry>
        </collision>
    </link>
    <!-- fixed joint between both sub-links -->
    <joint name="panda_link4_sc_joint" type="fixed">
        <origin rpy="0 0 0" />
        <parent link="panda_link4" />
        <child link="panda_link4_sc" />
    </joint>
    <joint name="panda_joint4" type="revolute">
        <origin rpy="1.5707963267948966 0 0" xyz="0.0825 0 0" />
        <parent link="panda_link3" />
        <child link="panda_link4" />
        <axis xyz="0 0 1" />
        <limit effort="87.0" lower="-3.0718" upper="-0.0698" velocity="2.175" />
        <safety_controller k_position="100.0" k_velocity="40.0" soft_lower_limit="-3.0718"
            soft_upper_limit="-0.0698" />
        <dynamics D="1" K="7000" damping="0.003" friction="0.0" mu_coulomb="0" mu_viscous="16" />
    </joint>
    <!-- sub-link defining detailed meshes for collision with environment -->
    <link name="panda_link5">
        <inertial>
            <origin xyz="-0.011953 0.041065 -0.038437" rpy="0 0 0" />
            <mass value="1.22595" />
            <inertia ixx="0.035549" ixy="-0.002117" ixz="-0.004037" iyy="0.029474" iyz="0.000229"
                izz="0.008627" />
        </inertial>
        <visual>
            <origin xyz="0 0 0" rpy="0 0 0" />
            <geometry>
                <mesh filename="package://franka_description/meshes/visual/link5.dae" />
            </geometry>
        </visual>
        <collision>
            <origin xyz="0 0 0" rpy="0 0 0" />
            <geometry>
                <mesh filename="package://franka_description/meshes/collision/link5.stl" />
            </geometry>
            <surface>
                <friction>
                    <ode mu="1" mu2="1" fdir1="0 0 0" slip1="0" slip2="0" />
                    <torsional coefficient="1" patch_radius="0" surface_radius="0"
                        use_patch_radius="1">
                        <ode slip="0" />
                    </torsional>
                </friction>
                <bounce restitution_coefficient="0" threshold="1e+06" />
                <contact>
                    <ode soft_cfm="0" soft_erp="0.2" kp="1e+13" kd="1" max_vel="0.01" min_depth="0" />
                    <bullet split_impulse="1" split_impulse_penetration_threshold="-0.01"
                        soft_cfm="0" soft_erp="0.2" kp="1e+13" kd="1" />
                </contact>
            </surface>
        </collision>
    </link>
    <!-- sub-link defining coarse geometries of real robot's internal self-collision -->
    <link name="panda_link5_sc">
        <collision>
            <origin rpy="0 0 0" xyz="0 0 -0.26" />
            <geometry>
                <cylinder length="0.1" radius="0.09" />
            </geometry>
        </collision>
        <collision>
            <origin xyz="0 0 -0.21000000000000002" />
            <geometry>
                <sphere radius="0.09" />
            </geometry>
        </collision>
        <collision>
            <origin xyz="0 0 -0.31" />
            <geometry>
                <sphere radius="0.09" />
            </geometry>
        </collision>
        <collision>
            <origin rpy="0 0 0.08" xyz="0 0.08 -0.13" />
            <geometry>
                <cylinder length="0.14" radius="0.055" />
            </geometry>
        </collision>
        <collision>
            <origin xyz="0 0.08 -0.06" />
            <geometry>
                <sphere radius="0.055" />
            </geometry>
        </collision>
        <collision>
            <origin xyz="0 0.08 -0.2" />
            <geometry>
                <sphere radius="0.055" />
            </geometry>
        </collision>
    </link>
    <!-- fixed joint between both sub-links -->
    <joint name="panda_link5_sc_joint" type="fixed">
        <origin rpy="0 0 0" />
        <parent link="panda_link5" />
        <child link="panda_link5_sc" />
    </joint>
    <joint name="panda_joint5" type="revolute">
        <origin rpy="-1.5707963267948966 0 0" xyz="-0.0825 0.384 0" />
        <parent link="panda_link4" />
        <child link="panda_link5" />
        <axis xyz="0 0 1" />
        <limit effort="12.0" lower="-2.8973" upper="2.8973" velocity="2.61" />
        <safety_controller k_position="100.0" k_velocity="40.0" soft_lower_limit="-2.8973"
            soft_upper_limit="2.8973" />
        <dynamics D="1" K="7000" damping="0.003" friction="0.0" mu_coulomb="0" mu_viscous="16" />
    </joint>
    <!-- sub-link defining detailed meshes for collision with environment -->
    <link name="panda_link6">
        <inertial>
            <origin xyz="0.060149 -0.014117 -0.010517" rpy="0 0 0" />
            <mass value="1.66656" />
            <inertia ixx="0.001964" ixy="0.000109" ixz="-0.001158" iyy="0.004354" iyz="0.000341"
                izz="0.005433" />
        </inertial>
        <visual>
            <origin xyz="0 0 0" rpy="0 0 0" />
            <geometry>
                <mesh filename="package://franka_description/meshes/visual/link6.dae" />
            </geometry>
        </visual>
        <collision>
            <origin xyz="0 0 0" rpy="0 0 0" />
            <geometry>
                <mesh filename="package://franka_description/meshes/collision/link6.stl" />
            </geometry>
            <surface>
                <friction>
                    <ode mu="1" mu2="1" fdir1="0 0 0" slip1="0" slip2="0" />
                    <torsional coefficient="1" patch_radius="0" surface_radius="0"
                        use_patch_radius="1">
                        <ode slip="0" />
                    </torsional>
                </friction>
                <bounce restitution_coefficient="0" threshold="1e+06" />
                <contact>
                    <ode soft_cfm="0" soft_erp="0.2" kp="1e+13" kd="1" max_vel="0.01" min_depth="0" />
                    <bullet split_impulse="1" split_impulse_penetration_threshold="-0.01"
                        soft_cfm="0" soft_erp="0.2" kp="1e+13" kd="1" />
                </contact>
            </surface>
        </collision>
    </link>
    <!-- sub-link defining coarse geometries of real robot's internal self-collision -->
    <link name="panda_link6_sc">
        <collision>
            <origin rpy="0 0 0" xyz="0 0 -0.03" />
            <geometry>
                <cylinder length="0.08" radius="0.08" />
            </geometry>
        </collision>
        <collision>
            <origin xyz="0 0 0.010000000000000002" />
            <geometry>
                <sphere radius="0.08" />
            </geometry>
        </collision>
        <collision>
            <origin xyz="0 0 -0.07" />
            <geometry>
                <sphere radius="0.08" />
            </geometry>
        </collision>
    </link>
    <!-- fixed joint between both sub-links -->
    <joint name="panda_link6_sc_joint" type="fixed">
        <origin rpy="0 0 0" />
        <parent link="panda_link6" />
        <child link="panda_link6_sc" />
    </joint>
    <joint name="panda_joint6" type="revolute">
        <origin rpy="1.5707963267948966 0 0" xyz="0 0 0" />
        <parent link="panda_link5" />
        <child link="panda_link6" />
        <axis xyz="0 0 1" />
        <limit effort="12.0" lower="-0.0175" upper="3.7525" velocity="2.61" />
        <safety_controller k_position="100.0" k_velocity="40.0" soft_lower_limit="-0.0175"
            soft_upper_limit="3.7525" />
        <dynamics D="1" K="7000" damping="0.003" friction="0.0" mu_coulomb="0" mu_viscous="16" />
    </joint>
    <!-- sub-link defining detailed meshes for collision with environment -->
    <link name="panda_link7">
        <inertial>
            <origin xyz="1.0517e-02 -4.252e-03 6.1597e-02" rpy="0 0 0" />
            <mass value="7.35522e-01" />
            <inertia ixx="1.2516e-02" ixy="-4.2800e-04" ixz="-1.1960e-03" iyy="1.0027e-02"
                iyz="-7.4100e-04" izz="4.8150e-03" />
        </inertial>
        <visual>
            <origin xyz="0 0 0" rpy="0 0 0" />
            <geometry>
                <mesh filename="package://franka_description/meshes/visual/link7.dae" />
            </geometry>
        </visual>
        <collision>
            <origin xyz="0 0 0" rpy="0 0 0" />
            <geometry>
                <mesh filename="package://franka_description/meshes/collision/link7.stl" />
            </geometry>
            <surface>
                <friction>
                    <ode mu="1" mu2="1" fdir1="0 0 0" slip1="0" slip2="0" />
                    <torsional coefficient="1" patch_radius="0" surface_radius="0"
                        use_patch_radius="1">
                        <ode slip="0" />
                    </torsional>
                </friction>
                <bounce restitution_coefficient="0" threshold="1e+06" />
                <contact>
                    <ode soft_cfm="0" soft_erp="0.2" kp="1e+13" kd="1" max_vel="0.01" min_depth="0" />
                    <bullet split_impulse="1" split_impulse_penetration_threshold="-0.01"
                        soft_cfm="0" soft_erp="0.2" kp="1e+13" kd="1" />
                </contact>
            </surface>
        </collision>
    </link>
    <!-- sub-link defining coarse geometries of real robot's internal self-collision -->
    <link name="panda_link7_sc">
        <collision>
            <origin rpy="0 0 0" xyz="0 0 0.01" />
            <geometry>
                <cylinder length="0.14" radius="0.07" />
            </geometry>
        </collision>
        <collision>
            <origin xyz="0 0 0.08" />
            <geometry>
                <sphere radius="0.07" />
            </geometry>
        </collision>
        <collision>
            <origin xyz="0 0 -0.060000000000000005" />
            <geometry>
                <sphere radius="0.07" />
            </geometry>
        </collision>
        <collision>
            <origin rpy="0 1.5707963267948966 0" xyz="0.06 0 0.082" />
            <geometry>
                <cylinder length="0.01" radius="0.06" />
            </geometry>
        </collision>
        <collision>
            <origin xyz="0.065 0 0.082" />
            <geometry>
                <sphere radius="0.06" />
            </geometry>
        </collision>
        <collision>
            <origin xyz="0.055 0 0.082" />
            <geometry>
                <sphere radius="0.06" />
            </geometry>
        </collision>
    </link>
    <!-- fixed joint between both sub-links -->
    <joint name="panda_link7_sc_joint" type="fixed">
        <origin rpy="0 0 0.7853981633974483" />
        <parent link="panda_link7" />
        <child link="panda_link7_sc" />
    </joint>
    <!-- add my code here model test -->
    <joint name="panda_joint7" type="revolute">
        <!-- this is the source code -->
        <origin rpy="1.5707963267948966 0 0" xyz="0.088 0 0" />
        <!-- delete this change -->
        <!-- <origin rpy="${pi/2} 0 0" xyz="0.088 -0.2104 0"/> -->
        <parent link="panda_link6" />
        <child link="panda_link7" />
        <axis xyz="0 0 1" />
        <limit effort="12.0" lower="-2.8973" upper="2.8973" velocity="2.61" />
        <safety_controller k_position="100.0" k_velocity="40.0" soft_lower_limit="-2.8973"
            soft_upper_limit="2.8973" />
        <dynamics D="1" K="7000" damping="0.003" friction="0.0" mu_coulomb="0" mu_viscous="16" />
    </joint>
    <link name="panda_link8" />
    <!-- add my code here model test -->
    <joint name="panda_joint8" type="fixed">
        <!-- this is the source code -->
        <origin rpy="0 0 0" xyz="0 0 0.107" />
        <!-- delete this change -->
        <!-- <origin rpy="0 0 0" xyz="0 0 0"/> -->
        <parent link="panda_link7" />
        <child link="panda_link8" />
    </joint>
    <!-- sub-link defining detailed meshes for collision with environment -->
    <link name="panda_hand">
        <inertial>
            <origin xyz="-0.01 0 0.03" rpy="0 0 0" />
            <mass value="0.73" />
            <inertia ixx="0.001" ixy="0" ixz="0" iyy="0.0025"
                iyz="0" izz="0.0017" />
        </inertial>
        <visual>
            <origin xyz="0 0 0" rpy="0 0 0" />
            <geometry>
                <mesh filename="package://franka_description/meshes/visual/hand.dae" />
            </geometry>
        </visual>
        <collision>
            <origin xyz="0 0 0" rpy="0 0 0" />
            <geometry>
                <mesh filename="package://franka_description/meshes/collision/hand.stl" />
            </geometry>
            <surface>
                <friction>
                    <ode mu="1" mu2="1" fdir1="0 0 0" slip1="0" slip2="0" />
                    <torsional coefficient="1" patch_radius="0" surface_radius="0"
                        use_patch_radius="1">
                        <ode slip="0" />
                    </torsional>
                </friction>
                <bounce restitution_coefficient="0" threshold="1e+06" />
                <contact>
                    <ode soft_cfm="0" soft_erp="0.2" kp="1e+13" kd="1" max_vel="0.01" min_depth="0" />
                    <bullet split_impulse="1" split_impulse_penetration_threshold="-0.01"
                        soft_cfm="0" soft_erp="0.2" kp="1e+13" kd="1" />
                </contact>
            </surface>
        </collision>
    </link>

    <joint name="panda_hand_joint" type="fixed">
        <parent link="panda_link8" />
        <child link="panda_hand" />
        <origin rpy="0 0 -0.7853981633974483" xyz="0 0 0" />
    </joint>
    <!-- sub-link defining coarse geometries of real robot's internal self-collision -->
    <link name="panda_hand_sc">
        <collision>
            <origin rpy="1.5707963267948966 0 0" xyz="0 0 0.04" />
            <geometry>
                <cylinder length="0.1" radius="0.07" />
            </geometry>
        </collision>
        <collision>
            <origin xyz="0 0.05 0.04" />
            <geometry>
                <sphere radius="0.07" />
            </geometry>
        </collision>
        <collision>
            <origin xyz="0 -0.05 0.04" />
            <geometry>
                <sphere radius="0.07" />
            </geometry>
        </collision>
        <collision>
            <origin rpy="1.5707963267948966 0 0" xyz="0 0 0.1" />
            <geometry>
                <cylinder length="0.1" radius="0.05" />
            </geometry>
        </collision>
        <collision>
            <origin xyz="0 0.05 0.1" />
            <geometry>
                <sphere radius="0.05" />
            </geometry>
        </collision>
        <collision>
            <origin xyz="0 -0.05 0.1" />
            <geometry>
                <sphere radius="0.05" />
            </geometry>
        </collision>
    </link>
    <!-- fixed joint between both sub-links -->
    <joint name="panda_hand_sc_joint" type="fixed">
        <origin rpy="0 0 0" />
        <parent link="panda_hand" />
        <child link="panda_hand_sc" />
    </joint>
    <!-- Define the hand_tcp frame -->
    <link name="panda_hand_tcp" />
    <joint name="panda_hand_tcp_joint" type="fixed">
        <origin rpy="0 0 0" xyz="0 0 0.1034" />
        <parent link="panda_hand" />
        <child link="panda_hand_tcp" />
    </joint>
    <link name="panda_leftfinger">
        <inertial>
            <origin xyz="0 0 0" rpy="0 0 0" />
            <mass value="0.015" />
            <inertia ixx="2.375e-06" ixy="0" ixz="0" iyy="2.375e-06" iyz="0" izz="7.5e-07" />
        </inertial>
        <visual>
            <origin xyz="0 0 0" rpy="0 0 0" />
            <geometry>
                <mesh filename="package://franka_description/meshes/visual/finger.dae" />
            </geometry>
        </visual>
        <!-- screw mount -->
        <collision>
            <origin rpy="0 0 0" xyz="0 18.5e-3 11e-3" />
            <geometry>
                <box size="22e-3 15e-3 20e-3" />
            </geometry>
            <surface>
                <friction>
                    <ode mu="1.13" mu2="1.13" fdir1="0 0 0" slip1="0" slip2="0" />
                    <torsional coefficient="1" patch_radius="0" surface_radius="0"
                        use_patch_radius="1">
                        <ode slip="0" />
                    </torsional>
                </friction>
                <bounce restitution_coefficient="0" threshold="1e+06" />
                <contact>
                    <ode soft_cfm="0" soft_erp="0.2" kp="1e+13" kd="1" max_vel="0" min_depth="0.001" />
                    <bullet split_impulse="1" split_impulse_penetration_threshold="-0.01"
                        soft_cfm="0" soft_erp="0.2" kp="1e+13" kd="1" />
                </contact>
            </surface>
        </collision>
        <!-- cartriage sledge -->
        <collision>
            <origin rpy="0 0 0" xyz="0 6.8e-3 2.2e-3" />
            <geometry>
                <box size="22e-3 8.8e-3 3.8e-3" />
            </geometry>
            <surface>
                <friction>
                    <ode mu="1.13" mu2="1.13" fdir1="0 0 0" slip1="0" slip2="0" />
                    <torsional coefficient="1" patch_radius="0" surface_radius="0"
                        use_patch_radius="1">
                        <ode slip="0" />
                    </torsional>
                </friction>
                <bounce restitution_coefficient="0" threshold="1e+06" />
                <contact>
                    <ode soft_cfm="0" soft_erp="0.2" kp="1e+13" kd="1" max_vel="0" min_depth="0.001" />
                    <bullet split_impulse="1" split_impulse_penetration_threshold="-0.01"
                        soft_cfm="0" soft_erp="0.2" kp="1e+13" kd="1" />
                </contact>
            </surface>
        </collision>
        <!-- diagonal finger -->
        <collision>
            <origin rpy="0.5235987755982988 0 0" xyz="0 15.9e-3 28.35e-3" />
            <geometry>
                <box size="17.5e-3 7e-3 23.5e-3" />
            </geometry>
            <surface>
                <friction>
                    <ode mu="1.13" mu2="1.13" fdir1="0 0 0" slip1="0" slip2="0" />
                    <torsional coefficient="1" patch_radius="0" surface_radius="0"
                        use_patch_radius="1">
                        <ode slip="0" />
                    </torsional>
                </friction>
                <bounce restitution_coefficient="0" threshold="1e+06" />
                <contact>
                    <ode soft_cfm="0" soft_erp="0.2" kp="1e+13" kd="1" max_vel="0"
                        min_depth="0.001" />
                    <bullet split_impulse="1" split_impulse_penetration_threshold="-0.01"
                        soft_cfm="0" soft_erp="0.2" kp="1e+13" kd="1" />
                </contact>
            </surface>
        </collision>
        <!-- rubber tip with which to grasp -->
        <collision>
            <origin rpy="0 0 0" xyz="0 7.58e-3 45.25e-3" />
            <geometry>
                <box size="17.5e-3 15.2e-3 18.5e-3" />
            </geometry>
            <surface>
                <friction>
                    <ode mu="1.13" mu2="1.13" fdir1="0 0 0"
                        slip1="0" slip2="0" />
                    <torsional coefficient="1" patch_radius="0" surface_radius="0"
                        use_patch_radius="1">
                        <ode slip="0" />
                    </torsional>
                </friction>
                <bounce restitution_coefficient="0" threshold="1e+06" />
                <contact>
                    <ode soft_cfm="0" soft_erp="0.2" kp="1e+13" kd="1" max_vel="0" min_depth="0.001" />
                    <bullet split_impulse="1" split_impulse_penetration_threshold="-0.01"
                        soft_cfm="0" soft_erp="0.2" kp="1e+13" kd="1" />
                </contact>
            </surface>
        </collision>
    </link>
    <link name="panda_rightfinger">
        <visual>
            <origin rpy="0 0 3.141592653589793" xyz="0 0 0" />
            <geometry>
                <mesh filename="package://franka_description/meshes/visual/finger.dae" />
            </geometry>
        </visual>
        <!-- screw mount -->
        <collision>
            <origin rpy="0 0 0" xyz="0 -18.5e-3 11e-3" />
            <geometry>
                <box size="22e-3 15e-3 20e-3" />
            </geometry>
        </collision>
        <!-- cartriage sledge -->
        <collision>
            <origin rpy="0 0 0" xyz="0 -6.8e-3 2.2e-3" />
            <geometry>
                <box size="22e-3 8.8e-3 3.8e-3" />
            </geometry>
        </collision>
        <!-- diagonal finger -->
        <collision>
            <origin rpy="-0.5235987755982988 0 0" xyz="0 -15.9e-3 28.35e-3" />
            <geometry>
                <box size="17.5e-3 7e-3 23.5e-3" />
            </geometry>
        </collision>
        <!-- rubber tip with which to grasp -->
        <collision>
            <origin rpy="0 0 0" xyz="0 -7.58e-3 45.25e-3" />
            <geometry>
                <box size="17.5e-3 15.2e-3 18.5e-3" />
            </geometry>
        </collision>
    </link>
    <!-- <joint name="panda_finger_joint1" type="prismatic">
    <parent link="panda_hand"/>
    <child link="panda_leftfinger"/>
    <origin rpy="0 0 0" xyz="0 0 0.0584"/>
    <axis xyz="0 1 0"/>
    <limit effort="100" lower="0.0" upper="0.04" velocity="0.2"/>
    <dynamics damping="0.3"/>
  </joint>
  <joint name="panda_finger_joint2" type="prismatic">
    <parent link="panda_hand"/>
    <child link="panda_rightfinger"/>
    <origin rpy="0 0 0" xyz="0 0 0.0584"/>
    <axis xyz="0 -1 0"/>
    <limit effort="100" lower="0.0" upper="0.04" velocity="0.2"/>
    <mimic joint="panda_finger_joint1"/>
    <dynamics damping="0.3"/>
  </joint> -->

    <!-- add my code here -->
    <joint name="panda_finger_joint1" type="fixed">
        <parent link="panda_hand" />
        <child link="panda_leftfinger" />
        <origin rpy="0 0 0" xyz="0 0 0.0584" />
    </joint>
    <joint name="panda_finger_joint2" type="fixed">
        <parent link="panda_hand" />
        <child link="panda_rightfinger" />
        <origin rpy="0 0 0" xyz="0 0 0.0584" />
    </joint>


</robot>